<?xml version="1.0" encoding="utf-8"?>
<!-- This URDF was automatically created by SolidWorks to URDF Exporter! Originally created by Stephen Brawner (brawner@gmail.com) 
     Commit Version: 1.6.0-4-g7f85cfe  Build Version: 1.6.7995.38578
     For more information, please see http://wiki.ros.org/sw_urdf_exporter -->
<robot
  name="hhhh">
  <link
    name="base_link">
    <inertial>
      <origin
        xyz="0.015666 -0.26923 0.13197"
        rpy="0 0 0" />
      <mass
        value="0.96406" />
      <inertia
        ixx="0.0040165"
        ixy="-1.1792E-07"
        ixz="-2.7124E-07"
        iyy="0.0039963"
        iyz="8.5518E-06"
        izz="0.0069121" />
    </inertial>
    <visual>
      <origin
        xyz="0 0 0"
        rpy="0 0 0" />
      <geometry>
        <mesh
          filename="package://hhhh/meshes/base_link.STL" />
      </geometry>
      <material
        name="">
        <color
          rgba="1 1 1 1" />
      </material>
    </visual>
    <collision>
      <origin
        xyz="0 0 0"
        rpy="0 0 0" />
      <geometry>
        <mesh
          filename="package://hhhh/meshes/base_link.STL" />
      </geometry>
    </collision>
  </link>
  <link
    name="r_base">
    <inertial>
      <origin
        xyz="0.0028918 0.026778 0.061531"
        rpy="0 0 0" />
      <mass
        value="1.1496" />
      <inertia
        ixx="0.0017061"
        ixy="-2.1851E-05"
        ixz="-1.4732E-06"
        iyy="0.0015053"
        iyz="-1.3775E-05"
        izz="0.0022896" />
    </inertial>
    <visual>
      <origin
        xyz="0 0 0"
        rpy="0 0 0" />
      <geometry>
        <mesh
          filename="package://hhhh/meshes/r_base.STL" />
      </geometry>
      <material
        name="">
        <color
          rgba="1 1 1 1" />
      </material>
    </visual>
    <collision>
      <origin
        xyz="0 0 0"
        rpy="0 0 0" />
      <geometry>
        <mesh
          filename="package://hhhh/meshes/r_base.STL" />
      </geometry>
    </collision>
  </link>
  <joint
    name="j1"
    type="revolute">
    <origin
      xyz="0.015675 -0.26952 0.13958"
      rpy="0 0 0" />
    <parent
      link="base_link" />
    <child
      link="r_base" />
    <axis
      xyz="0 0 -1" />
    <limit
      lower="-2.3562"
      upper="2.3562"
      effort="4.5"
      velocity="3.5" />
  </joint>
  <link
    name="shoulder">
    <inertial>
      <origin
        xyz="0.0085999 0.11155 0.0050414"
        rpy="0 0 0" />
      <mass
        value="0.35383" />
      <inertia
        ixx="0.00044067"
        ixy="-2.2382E-05"
        ixz="2.2542E-07"
        iyy="0.00015207"
        iyz="2.9308E-06"
        izz="0.00041391" />
    </inertial>
    <visual>
      <origin
        xyz="0 0 0"
        rpy="0 0 0" />
      <geometry>
        <mesh
          filename="package://hhhh/meshes/shoulder.STL" />
      </geometry>
      <material
        name="">
        <color
          rgba="1 1 1 1" />
      </material>
    </visual>
    <collision>
      <origin
        xyz="0 0 0"
        rpy="0 0 0" />
      <geometry>
        <mesh
          filename="package://hhhh/meshes/shoulder.STL" />
      </geometry>
    </collision>
  </link>
  <joint
    name="j2"
    type="revolute">
    <origin
      xyz="0 0 0.096"
      rpy="1.5708 0 -0.10746" />
    <parent
      link="r_base" />
    <child
      link="shoulder" />
    <axis
      xyz="0 0 -1" />
    <limit
      lower="-2.3562"
      upper="2.3562"
      effort="35"
      velocity="3.5" />
  </joint>
  <link
    name="elbow">
    <inertial>
      <origin
        xyz="-0.084232 0.06654 0.012158"
        rpy="0 0 0" />
      <mass
        value="0.38638" />
      <inertia
        ixx="0.00040194"
        ixy="9.9626E-05"
        ixz="1.0576E-05"
        iyy="0.00044937"
        iyz="-8.387E-06"
        izz="0.00031342" />
    </inertial>
    <visual>
      <origin
        xyz="0 0 0"
        rpy="0 0 0" />
      <geometry>
        <mesh
          filename="package://hhhh/meshes/elbow.STL" />
      </geometry>
      <material
        name="">
        <color
          rgba="1 1 1 1" />
      </material>
    </visual>
    <collision>
      <origin
        xyz="0 0 0"
        rpy="0 0 0" />
      <geometry>
        <mesh
          filename="package://hhhh/meshes/elbow.STL" />
      </geometry>
    </collision>
  </link>
  <joint
    name="j3"
    type="revolute">
    <origin
      xyz="0.016805 0.21735 0"
      rpy="0 0 0" />
    <parent
      link="shoulder" />
    <child
      link="elbow" />
    <axis
      xyz="0 0 1" />
    <limit
      lower="-2.3562"
      upper="2.3562"
      effort="15"
      velocity="3.5" />
  </joint>
  <link
    name="wrist">
    <inertial>
      <origin
        xyz="-0.0079871 -0.07975 -0.0021323"
        rpy="0 0 0" />
      <mass
        value="0.7592" />
      <inertia
        ixx="0.0039781"
        ixy="-0.00010087"
        ixz="3.5295E-07"
        iyy="0.00037187"
        iyz="4.8291E-06"
        izz="0.0037374" />
    </inertial>
    <visual>
      <origin
        xyz="0 0 0"
        rpy="0 0 0" />
      <geometry>
        <mesh
          filename="package://hhhh/meshes/wrist.STL" />
      </geometry>
      <material
        name="">
        <color
          rgba="1 1 1 1" />
      </material>
    </visual>
    <collision>
      <origin
        xyz="0 0 0"
        rpy="0 0 0" />
      <geometry>
        <mesh
          filename="package://hhhh/meshes/wrist.STL" />
      </geometry>
    </collision>
  </link>
  <joint
    name="j4"
    type="revolute">
    <origin
      xyz="-0.15373 0.12148 0"
      rpy="3.1416 0 0" />
    <parent
      link="elbow" />
    <child
      link="wrist" />
    <axis
      xyz="0 0 -1" />
    <limit
      lower="-2.3562"
      upper="2.3562"
      effort="4.5"
      velocity="3.5" />
  </joint>
</robot>